<mujoco model="leap grasp scene">
  <compiler angle="radian" meshdir="./assets/"/>
  <option impratio="100" integrator="implicitfast" cone="elliptic"/>
  <visual>
    <global azimuth="35" elevation="-50"/>
    <headlight ambient="0.3 0.3 0.3" diffuse="0.6 0.6 0.6" specular="0 0 0"/>
    <rgba haze="0.15 0.25 0.35 1"/>
  </visual>
  <statistic extent="0.3" center="0 0 0.1"/>
  <default class="main">
    <joint damping="0.03" frictionloss="0.001"/>
    <geom friction="0.2" solref="0.0001" solimp="0.999 0.999 0.001 0.0001 1"/>
    <general biastype="affine" gainprm="3" biasprm="0 -3 -0.01"/>
    <default class="visual">
      <geom type="mesh" contype="0" conaffinity="0" group="1" density="0" material="black"/>
    </default>
    <default class="collision">
      <geom material="black"/>
    </default>
    <default class="tip">
      <geom type="mesh" friction="0.5" material="white" mesh="tip"/>
    </default>
    <default class="thumb_tip">
      <geom type="mesh" friction="0.5" material="white" mesh="thumb_tip"/>
    </default>
    <default class="mcp">
      <joint limited="true" range="-0.314 2.23"/>
      <general ctrlrange="-0.314 2.23"/>
    </default>
    <default class="rot">
      <joint limited="true" range="-1.047 1.047"/>
      <general ctrlrange="-1.047 1.047"/>
    </default>
    <default class="pip">
      <joint limited="true" range="-0.506 1.885"/>
      <general ctrlrange="-0.506 1.885"/>
    </default>
    <default class="dip">
      <joint limited="true" range="-0.366 2.042"/>
      <general ctrlrange="-0.366 2.042"/>
    </default>
    <default class="thumb_cmc">
      <joint limited="true" range="-0.349 2.094"/>
      <general ctrlrange="-0.349 2.094"/>
    </default>
    <default class="thumb_axl">
      <joint limited="true" range="-0.349 2.094"/>
      <general ctrlrange="-0.349 2.094"/>
    </default>
    <default class="thumb_mcp">
      <joint limited="true" range="-0.47 2.443"/>
      <general ctrlrange="-0.47 2.443"/>
    </default>
    <default class="thumb_ipl">
      <joint limited="true" range="-1.34 1.88"/>
      <general ctrlrange="-1.34 1.88"/>
    </default>
  </default>
  <asset>
    <texture type="skybox" builtin="gradient" rgb1="0.3 0.5 0.7" rgb2="0 0 0" width="512" height="3072"/>
    <texture type="2d" name="groundplane" builtin="checker" mark="edge" rgb1="0.2 0.3 0.4" rgb2="0.1 0.2 0.3" markrgb="0.8 0.8 0.8" width="300" height="300"/>
    <material name="black" rgba="0.2 0.2 0.2 1"/>
    <material name="white"/>
    <material name="groundplane" texture="groundplane" texuniform="true" texrepeat="5 5" reflectance="0.2"/>
    <mesh name="palm" file="palm_right.obj"/>
    <mesh name="base" file="base.obj"/>
    <mesh name="proximal" file="proximal.obj"/>
    <mesh name="medial" file="medial.obj"/>
    <mesh name="distal" file="distal.obj"/>
    <mesh name="tip" file="tip.obj"/>
    <mesh name="thumb_base" file="thumb_base.obj"/>
    <mesh name="thumb_proximal" file="thumb_proximal.obj"/>
    <mesh name="thumb_distal" file="thumb_distal.obj"/>
    <mesh name="thumb_tip" file="thumb_tip.obj"/>
  </asset>
  <worldbody>
    <geom name="floor" size="0 0 0.05" type="plane" material="groundplane"/>
    <light pos="0 0 1.5" dir="0 0 -1" directional="true"/>
    <body name="palm" pos="0 0 0.1" quat="0 1 0 0">
      <inertial pos="-0.049542 -0.042914 -0.010227" quat="0.565586 0.427629 -0.574956 0.408254" mass="0.237" diaginertia="0.000407345 0.000304759 0.000180736"/>
      <geom name="palm_visual" class="visual" pos="-0.02 0.02575 -0.0347" mesh="palm"/>
      <geom name="palm_collision_1" class="collision" size="0.011 0.013 0.017" pos="-0.009 0.008 -0.011" type="box"/>
      <geom name="palm_collision_2" class="collision" size="0.011 0.013 0.017" pos="-0.009 -0.037 -0.011" type="box"/>
      <geom name="palm_collision_3" class="collision" size="0.011 0.013 0.017" pos="-0.009 -0.082 -0.011" type="box"/>
      <geom name="palm_collision_4" class="collision" size="0.029 0.01 0.023" pos="-0.066 -0.078 -0.0115" quat="0.989016 0 0 -0.147806" type="box"/>
      <geom name="palm_collision_5" class="collision" size="0.01 0.06 0.015" pos="-0.03 -0.035 -0.003" type="box"/>
      <geom name="palm_collision_6" class="collision" size="0.005 0.06 0.01" pos="-0.032 -0.035 -0.024" quat="0.923956 0 0.382499 0" type="box"/>
      <geom name="palm_collision_7" class="collision" size="0.012 0.058 0.023" pos="-0.048 -0.033 -0.0115" type="box"/>
      <geom name="palm_collision_8" class="collision" size="0.022 0.026 0.023" pos="-0.078 -0.053 -0.0115" type="box"/>
      <geom name="palm_collision_9" class="collision" size="0.002 0.018 0.017" pos="-0.098 -0.009 -0.006" type="box"/>
      <geom name="palm_collision_10" class="collision" size="0.022 0.028 0.002" pos="-0.078 -0.003 0.01" type="box"/>
      <body name="if_bs" pos="-0.007 0.023 -0.0187" quat="0.500003 0.5 0.5 -0.499997">
        <inertial pos="-0.022516 0.033882 0.016359" quat="0.388092 0.677951 -0.247713 0.573067" mass="0.044" diaginertia="1.74972e-05 1.61504e-05 7.21342e-06"/>
        <joint name="if_mcp" class="mcp" pos="0 0 0" axis="0 0 -1"/>
        <geom name="if_bs_visual" class="visual" pos="0.0084 0.0077 0.01465" mesh="base"/>
        <geom name="if_bs_collision_1" class="collision" size="0.01 0.003 0.017" pos="0 0.018 0.0147" type="box"/>
        <geom name="if_bs_collision_2" class="collision" size="0.014 0.02 0.01" pos="-0.027 0.042 0.015" type="box"/>
        <geom name="if_bs_collision_3" class="collision" size="0.017 0.003 0.01" pos="-0.0262 0.02 0.0146" type="box"/>
        <geom name="if_bs_collision_4" class="collision" size="0.01 0.012 0.004" pos="-0.0295 0.035 0.029" type="box"/>
        <geom name="if_bs_collision_5" class="collision" size="0.007 0.01 0.002" pos="0 0.005 0.03" type="box"/>
        <geom name="if_bs_collision_6" class="collision" size="0.007 0.01 0.002" pos="0 0.005 -0.001" type="box"/>
        <body name="if_px" pos="-0.0122 0.0381 0.0145" quat="0.500003 -0.5 -0.499997 0.5">
          <inertial pos="0.0075 -0.0002 -0.011" quat="0 0.707107 0 0.707107" mass="0.032" diaginertia="4.8853e-06 4.3733e-06 3.0933e-06"/>
          <joint name="if_rot" class="rot" pos="0 0 0" axis="0 0 -1"/>
          <geom name="if_px_visual" class="visual" pos="0.0096 0.0002 0.0007" quat="0.500003 -0.5 -0.5 -0.499997" mesh="proximal"/>
          <geom name="if_px_collision" class="collision" size="0.017 0.013 0.011" pos="0.0075 -0.0002 -0.011" type="box"/>
          <body name="if_md" pos="0.015 0.0143 -0.013" quat="0.500003 0.5 -0.5 0.499997">
            <inertial pos="0.0054215 -0.029148 0.015" quat="0.687228 0.687228 0.166487 0.166487" mass="0.037" diaginertia="8.28004e-06 8.1598e-06 5.39516e-06"/>
            <joint name="if_pip" class="pip" pos="0 0 0" axis="0 0 -1"/>
            <geom name="if_md_visual" class="visual" pos="0.0211 -0.0084 0.0097" quat="2.67949e-08 -1 0 0" mesh="medial"/>
            <geom name="if_md_collision_1" class="collision" size="0.008 0.003 0.013" pos="0 -0.02 0.015" type="box"/>
            <geom name="if_md_collision_2" class="collision" size="0.01 0.002 0.017" pos="0 -0.016 0.015" type="box"/>
            <geom name="if_md_collision_3" class="collision" size="0.007 0.01 0.002" pos="0 -0.0045 0.03" type="box"/>
            <geom name="if_md_collision_4" class="collision" size="0.007 0.01 0.002" pos="0 -0.0045 0" type="box"/>
            <geom name="if_md_collision_5" class="collision" size="0.017 0.011 0.013" pos="0.0075 -0.035 0.015" type="box"/>
            <body name="if_ds" pos="0 -0.0361 0.0002">
              <inertial pos="-0.0008794 -0.027019 0.014594" quat="0.702905 0.710643 -0.0212937 -0.0214203" mass="0.016" diaginertia="3.71863e-06 3.02396e-06 1.6518e-06"/>
              <joint name="if_dip" class="dip" pos="0 0 0" axis="0 0 -1"/>
              <geom name="if_ds_visual" class="visual" pos="0.0132 -0.0061 0.0144" quat="2.67949e-08 1 0 0" mesh="distal"/>
              <geom name="if_ds_collision_1" class="collision" size="0.01 0.003 0.015" pos="0 -0.017 0.015" type="box"/>
              <geom name="if_ds_collision_2" class="collision" size="0.007 0.011 0.002" pos="0 -0.006 0.03" type="box"/>
              <geom name="if_ds_collision_3" class="collision" size="0.007 0.011 0.002" pos="0 -0.006 -0.001" type="box"/>
              <geom name="if_tip" class="tip" mesh="tip"/>
            </body>
          </body>
        </body>
      </body>
      <body name="mf_bs" pos="-0.0071 -0.0224 -0.0187" quat="0.500003 0.5 0.5 -0.499997">
        <inertial pos="-0.022516 0.033882 0.016359" quat="0.388092 0.677951 -0.247713 0.573067" mass="0.044" diaginertia="1.74972e-05 1.61504e-05 7.21342e-06"/>
        <joint name="mf_mcp" class="mcp" pos="0 0 0" axis="0 0 -1"/>
        <geom name="mf_bs_visual" class="visual" pos="0.0084 0.0077 0.01465" mesh="base"/>
        <geom name="mf_bs_collision_1" class="collision" size="0.01 0.003 0.017" pos="0 0.018 0.0147" type="box"/>
        <geom name="mf_bs_collision_2" class="collision" size="0.014 0.02 0.01" pos="-0.027 0.042 0.015" type="box"/>
        <geom name="mf_bs_collision_3" class="collision" size="0.017 0.003 0.01" pos="-0.0262 0.02 0.0146" type="box"/>
        <geom name="mf_bs_collision_4" class="collision" size="0.01 0.012 0.004" pos="-0.0295 0.035 0.029" type="box"/>
        <geom name="mf_bs_collision_5" class="collision" size="0.007 0.01 0.002" pos="0 0.005 0.03" type="box"/>
        <geom name="mf_bs_collision_6" class="collision" size="0.007 0.01 0.002" pos="0 0.005 -0.001" type="box"/>
        <body name="mf_px" pos="-0.0122 0.0381 0.0145" quat="0.500003 -0.5 -0.499997 0.5">
          <inertial pos="0.0075 -0.0002 -0.011" quat="0 0.707107 0 0.707107" mass="0.032" diaginertia="4.8853e-06 4.3733e-06 3.0933e-06"/>
          <joint name="mf_rot" class="rot" pos="0 0 0" axis="0 0 -1"/>
          <geom name="mf_px_visual" class="visual" pos="0.0096 0.0003 0.0007" quat="0.500003 -0.5 -0.5 -0.499997" mesh="proximal"/>
          <geom name="mf_px_collision" class="collision" size="0.017 0.013 0.011" pos="0.0075 -0.0002 -0.011" type="box"/>
          <body name="mf_md" pos="0.015 0.0143 -0.013" quat="0.500003 0.5 -0.5 0.499997">
            <inertial pos="0.0054215 -0.029148 0.015" quat="0.687228 0.687228 0.166487 0.166487" mass="0.037" diaginertia="8.28004e-06 8.1598e-06 5.39516e-06"/>
            <joint name="mf_pip" class="pip" pos="0 0 0" axis="0 0 -1"/>
            <geom name="mf_md_visual" class="visual" pos="0.0211 -0.0084 0.0097" quat="1.32679e-06 -1 0 0" mesh="medial"/>
            <geom name="mf_md_collision_1" class="collision" size="0.008 0.003 0.013" pos="0 -0.02 0.015" type="box"/>
            <geom name="mf_md_collision_2" class="collision" size="0.01 0.002 0.017" pos="0 -0.016 0.015" type="box"/>
            <geom name="mf_md_collision_3" class="collision" size="0.007 0.01 0.002" pos="0 -0.0045 0.03" type="box"/>
            <geom name="mf_md_collision_4" class="collision" size="0.007 0.01 0.002" pos="0 -0.0045 0" type="box"/>
            <geom name="mf_md_collision_5" class="collision" size="0.017 0.011 0.013" pos="0.0075 -0.035 0.015" type="box"/>
            <body name="mf_ds" pos="0 -0.0361 0.0002">
              <inertial pos="-0.0008794 -0.027019 0.014594" quat="0.702905 0.710643 -0.0212937 -0.0214203" mass="0.016" diaginertia="3.71863e-06 3.02396e-06 1.6518e-06"/>
              <joint name="mf_dip" class="dip" pos="0 0 0" axis="0 0 -1"/>
              <geom name="mf_ds_visual" class="visual" pos="0.0132 -0.0061 0.0145" quat="1.32679e-06 1 0 0" mesh="distal"/>
              <geom name="mf_ds_collision_1" class="collision" size="0.01 0.003 0.015" pos="0 -0.017 0.015" type="box"/>
              <geom name="mf_ds_collision_2" class="collision" size="0.007 0.011 0.002" pos="0 -0.006 0.03" type="box"/>
              <geom name="mf_ds_collision_3" class="collision" size="0.007 0.011 0.002" pos="0 -0.006 -0.001" type="box"/>
              <geom name="mf_tip" class="tip" mesh="tip"/>
            </body>
          </body>
        </body>
      </body>
      <body name="rf_bs" pos="-0.00709 -0.0678 -0.0187" quat="0.500003 0.5 0.5 -0.499997">
        <inertial pos="-0.022516 0.033882 0.016359" quat="0.388092 0.677951 -0.247713 0.573067" mass="0.044" diaginertia="1.74972e-05 1.61504e-05 7.21342e-06"/>
        <joint name="rf_mcp" class="mcp" pos="0 0 0" axis="0 0 -1"/>
        <geom name="rf_bs_visual" class="visual" pos="0.0084 0.0077 0.01465" mesh="base"/>
        <geom name="rf_bs_collision_1" class="collision" size="0.01 0.003 0.017" pos="0 0.018 0.0147" type="box"/>
        <geom name="rf_bs_collision_2" class="collision" size="0.014 0.02 0.01" pos="-0.027 0.042 0.015" type="box"/>
        <geom name="rf_bs_collision_3" class="collision" size="0.017 0.003 0.01" pos="-0.0262 0.02 0.0146" type="box"/>
        <geom name="rf_bs_collision_4" class="collision" size="0.01 0.012 0.004" pos="-0.0295 0.035 0.029" type="box"/>
        <geom name="rf_bs_collision_5" class="collision" size="0.007 0.01 0.002" pos="0 0.005 0.03" type="box"/>
        <geom name="rf_bs_collision_6" class="collision" size="0.007 0.01 0.002" pos="0 0.005 -0.001" type="box"/>
        <body name="rf_px" pos="-0.0122 0.0381 0.0145" quat="0.500003 -0.5 -0.499997 0.5">
          <inertial pos="0.0075 -0.0002 -0.011" quat="0 0.707107 0 0.707107" mass="0.032" diaginertia="4.8853e-06 4.3733e-06 3.0933e-06"/>
          <joint name="rf_rot" class="rot" pos="0 0 0" axis="0 0 -1"/>
          <geom name="rf_px_visual" class="visual" pos="0.0096 0.0003 0.0007" quat="0.500003 -0.5 -0.5 -0.499997" mesh="proximal"/>
          <geom name="rf_px_collision" class="collision" size="0.017 0.013 0.011" pos="0.0075 -0.0002 -0.011" type="box"/>
          <body name="rf_md" pos="0.015 0.0143 -0.013" quat="0.500003 0.5 -0.5 0.499997">
            <inertial pos="0.0054215 -0.029148 0.015" quat="0.687228 0.687228 0.166487 0.166487" mass="0.037" diaginertia="8.28004e-06 8.1598e-06 5.39516e-06"/>
            <joint name="rf_pip" class="pip" pos="0 0 0" axis="0 0 -1"/>
            <geom name="rf_md_visual" class="visual" pos="0.0211 -0.0084 0.0097" quat="1.32679e-06 -1 0 0" mesh="medial"/>
            <geom name="rf_md_collision_1" class="collision" size="0.008 0.003 0.013" pos="0 -0.02 0.015" type="box"/>
            <geom name="rf_md_collision_2" class="collision" size="0.01 0.002 0.017" pos="0 -0.016 0.015" type="box"/>
            <geom name="rf_md_collision_3" class="collision" size="0.007 0.01 0.002" pos="0 -0.0045 0.03" type="box"/>
            <geom name="rf_md_collision_4" class="collision" size="0.007 0.01 0.002" pos="0 -0.0045 0" type="box"/>
            <geom name="rf_md_collision_5" class="collision" size="0.017 0.011 0.013" pos="0.0075 -0.035 0.015" type="box"/>
            <body name="rf_ds" pos="0 -0.03609 0.0002">
              <inertial pos="-0.0008794 -0.027019 0.014594" quat="0.702905 0.710643 -0.0212937 -0.0214203" mass="0.016" diaginertia="3.71863e-06 3.02396e-06 1.6518e-06"/>
              <joint name="rf_dip" class="dip" pos="0 0 0" axis="0 0 -1"/>
              <geom name="rf_ds_visual" class="visual" pos="0.0132 -0.0061 0.0145" quat="1.32679e-06 1 0 0" mesh="distal"/>
              <geom name="rf_ds_collision_1" class="collision" size="0.01 0.003 0.015" pos="0 -0.017 0.015" type="box"/>
              <geom name="rf_ds_collision_2" class="collision" size="0.007 0.011 0.002" pos="0 -0.006 0.03" type="box"/>
              <geom name="rf_ds_collision_3" class="collision" size="0.007 0.011 0.002" pos="0 -0.006 -0.001" type="box"/>
              <geom name="rf_tip" class="tip" mesh="tip"/>
            </body>
          </body>
        </body>
      </body>
      <body name="th_mp" pos="-0.0693 -0.0012 -0.0216" quat="0.707109 0 0.707105 0">
        <inertial pos="0.0075 -0.0002 -0.011" quat="0 0.707107 0 0.707107" mass="0.032" diaginertia="4.8853e-06 4.3733e-06 3.0933e-06"/>
        <joint name="th_cmc" class="thumb_cmc" pos="0 0 0" axis="0 0 -1"/>
        <geom name="th_mp_visual" class="visual" pos="-0.0053 0.0003 0.00078" quat="0.500003 -0.5 -0.5 -0.499997" mesh="proximal"/>
        <geom name="th_mp_collision" class="collision" size="0.017 0.013 0.011" pos="-0.0075 -0.0002 -0.011" type="box"/>
        <body name="th_bs" pos="0 0.0143 -0.013" quat="0.500003 0.5 -0.5 0.499997">
          <inertial pos="0 0 -0.0070806" quat="0.707107 0.707107 0 0" mass="0.003" diaginertia="6.1932e-07 5.351e-07 2.1516e-07"/>
          <joint name="th_axl" class="thumb_axl" pos="0 0 0" axis="0 0 -1"/>
          <geom name="th_bs_visual" class="visual" pos="0.01196 0 -0.0158" quat="0.707109 0.707105 0 0" mesh="thumb_base"/>
          <geom name="th_bs_collision_1" class="collision" size="0.009 0.0165 0.002" pos="0 0 -0.0015" type="box"/>
          <geom name="th_bs_collision_2" class="collision" size="0.007 0.002 0.01" pos="0 -0.015 -0.013" type="box"/>
          <geom name="th_bs_collision_3" class="collision" size="0.007 0.002 0.01" pos="0 0.015 -0.013" type="box"/>
          <body name="th_px" pos="0 0.0145 -0.017" quat="0.707109 -0.707105 0 0">
            <inertial pos="-0.0020593 0.015912 -0.013733" quat="0.698518 0.697382 -0.104933 0.121324" mass="0.038" diaginertia="9.87104e-06 9.32653e-06 4.36203e-06"/>
            <joint name="th_mcp" class="thumb_mcp" pos="0 0 0" axis="0 0 -1"/>
            <geom name="th_px_visual" class="visual" pos="0.0439 0.0579 -0.0086" mesh="thumb_proximal"/>
            <geom name="th_px_collision_1" class="collision" size="0.01 0.02 0.012" pos="0 0.0105 -0.014" type="box"/>
            <geom name="th_px_collision_2" class="collision" size="0.01 0.002 0.016" pos="0 0.031 -0.015" type="box"/>
            <geom name="th_px_collision_3" class="collision" size="0.007 0.01 0.002" pos="0 0.042 0.001" type="box"/>
            <geom name="th_px_collision_4" class="collision" size="0.007 0.01 0.002" pos="0 0.042 -0.029" type="box"/>
            <geom name="th_px_collision_5" class="collision" size="0.005 0.012 0.009" pos="-0.0135 0.0175 -0.011656" type="box"/>
            <body name="th_ds" pos="0 0.0466 0.0002" quat="1.32679e-06 0 0 1">
              <inertial pos="0.00096191 -0.024203 -0.014419" quat="0.35287 0.311272 -0.632839 0.614904" mass="0.049" diaginertia="2.08591e-05 2.0402e-05 4.71335e-06"/>
              <joint name="th_ipl" class="thumb_ipl" pos="0 0 0" axis="0 0 -1"/>
              <geom name="th_ds_visual" class="visual" pos="0.0625 0.0784 0.0489" mesh="thumb_distal"/>
              <geom name="th_ds_collision_1" class="collision" size="0.01 0.018 0.012" pos="0 -0.0085 -0.015" type="box"/>
              <geom name="th_ds_collision_2" class="collision" size="0.01 0.002 0.015" pos="0 -0.029 -0.014" type="box"/>
              <geom name="th_ds_collision_3" class="collision" size="0.004 0.012 0.009" pos="0.015 -0.0175 -0.0115" type="box"/>
              <geom name="th_tip" class="thumb_tip" mesh="thumb_tip"/>
            </body>
          </body>
        </body>
      </body>
    </body>
    <body name="table">
      <geom name="table_top" size="0.3 0.3 0.025" pos="0 0 0.025" type="box" rgba="0.6 0.4 0.2 1"/>
    </body>
    <body name="object" pos="0 0 0.075">
      <joint name="object_joint" type="free" limited="false" actuatorfrclimited="false" damping="0" frictionloss="0"/>
      <geom name="cube" size="0.025 0.025 0.025" type="box" friction="1.5 0.1 0.1" mass="0.05" rgba="1 0.2 0.2 1"/>
    </body>
  </worldbody>
  <contact>
    <exclude body1="palm" body2="if_bs"/>
    <exclude body1="palm" body2="if_px"/>
    <exclude body1="palm" body2="if_md"/>
    <exclude body1="palm" body2="mf_bs"/>
    <exclude body1="palm" body2="mf_px"/>
    <exclude body1="palm" body2="mf_md"/>
    <exclude body1="palm" body2="rf_bs"/>
    <exclude body1="palm" body2="rf_px"/>
    <exclude body1="palm" body2="rf_md"/>
    <exclude body1="palm" body2="th_mp"/>
    <exclude body1="palm" body2="th_bs"/>
    <exclude body1="palm" body2="th_px"/>
    <exclude body1="if_bs" body2="mf_bs"/>
    <exclude body1="if_bs" body2="rf_bs"/>
    <exclude body1="if_bs" body2="th_mp"/>
    <exclude body1="mf_bs" body2="rf_bs"/>
    <exclude body1="mf_bs" body2="th_mp"/>
    <exclude body1="rf_bs" body2="th_mp"/>
  </contact>
  <actuator>
    <general name="if_mcp_act" class="mcp" joint="if_mcp"/>
    <general name="if_rot_act" class="rot" joint="if_rot"/>
    <general name="if_pip_act" class="pip" joint="if_pip"/>
    <general name="if_dip_act" class="dip" joint="if_dip"/>
    <general name="mf_mcp_act" class="mcp" joint="mf_mcp"/>
    <general name="mf_rot_act" class="rot" joint="mf_rot"/>
    <general name="mf_pip_act" class="pip" joint="mf_pip"/>
    <general name="mf_dip_act" class="dip" joint="mf_dip"/>
    <general name="rf_mcp_act" class="mcp" joint="rf_mcp"/>
    <general name="rf_rot_act" class="rot" joint="rf_rot"/>
    <general name="rf_pip_act" class="pip" joint="rf_pip"/>
    <general name="rf_dip_act" class="dip" joint="rf_dip"/>
    <general name="th_cmc_act" class="thumb_cmc" joint="th_cmc"/>
    <general name="th_axl_act" class="thumb_axl" joint="th_axl"/>
    <general name="th_mcp_act" class="thumb_mcp" joint="th_mcp"/>
    <general name="th_ipl_act" class="thumb_ipl" joint="th_ipl"/>
  </actuator>
  <sensor>
    <jointpos joint="if_mcp" name="if_mcp_sensor"/>
    <jointpos joint="if_rot" name="if_rot_sensor"/>
    <jointpos joint="if_pip" name="if_pip_sensor"/>
    <jointpos joint="if_dip" name="if_dip_sensor"/>
    <jointpos joint="mf_mcp" name="mf_mcp_sensor"/>
    <jointpos joint="mf_rot" name="mf_rot_sensor"/>
    <jointpos joint="mf_pip" name="mf_pip_sensor"/>
    <jointpos joint="mf_dip" name="mf_dip_sensor"/>
    <jointpos joint="rf_mcp" name="rf_mcp_sensor"/>
    <jointpos joint="rf_rot" name="rf_rot_sensor"/>
    <jointpos joint="rf_pip" name="rf_pip_sensor"/>
    <jointpos joint="rf_dip" name="rf_dip_sensor"/>
    <jointpos joint="th_cmc" name="th_cmc_sensor"/>
    <jointpos joint="th_axl" name="th_axl_sensor"/>
    <jointpos joint="th_mcp" name="th_mcp_sensor"/>
    <jointpos joint="th_ipl" name="th_ipl_sensor"/>
  </sensor>
</mujoco>
